Workbook
Name a: #REF!
Name a: #REF!
Name Attendance: #REF!
Name Attendance: #REF!
Name BSDStatus: #REF!
Name Effort: #REF!
Name fhgcnhfv: '[1]Drop Down Fields'!$D$16:$D$19
Name FollowUPCategory: #REF!
Name FollowUpStatus: #REF!
Name FSDStatus: #REF!
Name GapPriority: #REF!
Name GapStatus: #REF!
Name Level: #REF!
Name MoSCoW: #REF!
Name NewGapStatus: #REF!
Name NewGapType: #REF!
Name Owner: #REF!
Name Priority: #REF!
Name ProcessStatus: #REF!
Name RAG: #REF!
Name ScopingGapStatus: #REF!
Name ScopingGapType: #REF!
Name Status: #REF!

Sheet Day1 - E2E Accounting Entries
A1: Stage | B1: Debit/Credit | C1: Accounting Entries | D1: Description | E1: Core/ Customized | F1: Account Reflection
A2: Status - Request | B2: DR | C2: No Accounting Entry | H2: Finance Amount | J2: 10000
B3: CR | H3: Admin Fee 1% | J3: =J2*1% -> 100
A4: Status - Approval | B4: DR | C4: GIT | D4: Goods in Transit | E4: =-J2 -> -10000 | F4: On Balance Sheet | H4: VAT | J4: =J3*15% -> 15
B5: CR | C5: Purchase Order | D5: Purchase Order | E5: =-E4 -> 10000 | F5: On Balance Sheet | H5: Net Finance Amount | J5: =J2-J3-J4 -> 9885
A6: Status - Purchase | B6: DR | C6: Purchase Order | D6: Purchase Order | E6: =-E5 -> -10000 | F6: On Balance Sheet
B7: CR | C7: GIT | D7: Goods in Transit | E7: =-E5 -> -10000 | F7: On Balance Sheet | H7: Profit Amount | I7: 0.12 | J7: =J2*I7 -> 1200
B8: DR | C8: Purchases | D8: Purchase | E8: =-J2 -> -10000 | F8: On Balance Sheet
B9: CR | C9: Buy Broker's account | D9: Internal Account | E9: =-E8 -> 10000 | F9: On Balance Sheet
A10: Finance / Sale | B10: DR | C10: CURACCOUNT | D10: AA Arrangeement - ACCOUNT | E10: =-J2 -> -10000 | F10: On Balance Sheet | H10: Back
B11: CR | C11: Purchases | D11: Purchase | E11: =-E8 -> 10000 | F11: On Balance Sheet
B12: DR | C12: RECDEFPFT | D12: Profit Receivable | E12: =-J7 -> -1200 | F12: On Balance Sheet
B13: CR | C13: ACCDEFPFT | D13: Unearned Accrued Profit | E13: =-E12 -> 1200 | F13: On Balance Sheet
A14: Admin Fee Due with VAT | B14: Dr | C14: DUEADMINFEE | D14: Admin Fee | E14: =-J3 -> -100
B15: Cr | C15: ACCADMINFEE | D15: Unamortise Admin Fee | E15: =-E14 -> 100
B16: Dr | C16: DUEVAT | D16: VAT Receivable | E16: =-J4 -> -15
B17: Cr | C17: VAT Payable | E17: =-E16 -> 15
A18: Payment to Customer | B18: DR | C18: Sell Broker's Account | D18: Internal Account | E18: -10000 | F18: On Balance Sheet
B19: CR | C19: Customer's Account | D19: Disbursment/Repayment Account | E19: 10000 | F19: On Balance Sheet | G19: 1
A20: Broker Settlement (incase of different) | B20: DR | C20: Buy Broker's Account | D20: Internal Account | E20: =-E9 -> -10000 | F20: On Balance Sheet
B21: CR | C21: Sell Broker's Account | D21: Internal Account | E21: =-E18 -> 10000 | F21: On Balance Sheet
A22: Recovery of Admin Fee & VAT | B22: Dr | C22: Customer's Account | D22: Disbursment/Repayment Account | E22: =E14 -> -100
B23: Cr | C23: DUEADMINFEE | D23: Admin Fee | E23: =-E14 -> 100
B24: Dr | C24: Customer's Account | D24: Disbursment/Repayment Account | E24: =E16 -> -15
B25: Cr | C25: DUEVAT | D25: VAT | E25: =-E16 -> 15
A26: Actual Repayment to Customer (Net of Financing) | B26: Dr | C26: Customer's Account | D26: Disbursment/Repayment Account | E26: =E19+E22+E24 -> 9885
B27: Cr | C27: BF Account | D27: Internal Account | E27: =-E26 -> -9885
B28: Dr | C28: BF Account | D28: Internal Account | E28: =E26 -> 9885
B29: Cr | C29: Customer Bank Account | D29: XYZ bank account- customer current account | E29: =E27 -> -9885
A30: Upfront Admin Fee By Customer | B30: Dr | C30: BF Account | D30: Internal Account | E30: =E22+E24 -> -115
B31: Cr | C31: Customer's Account | D31: Disbursment/Repayment Account | E31: =-E30 -> 115
A32: Actual Repayment to Customer (Full Financing) | B32: Dr | C32: Customer's Account | D32: Disbursment/Repayment Account | E32: =E19+E22+E24+E31 -> 10000
B33: Cr | C33: BF Account | D33: Internal Account | E33: =-E32 -> -10000
B34: Dr | C34: BF Account | D34: Internal Account | E34: =E32 -> 10000
B35: Cr | C35: Customer Bank Account | D35: XYZ bank account- customer current account | E35: =E33 -> -10000
A37: Daily Amortization Profit based on reducing balance | B37: DR | C37: ACCDEFPFT | D37: Unearned Accrued Profit | E37: =-E13/365 -> -3.2876712 | F37: On Balance Sheet
B38: CR | C38: PL/ Income | D38: PL Category | E38: =-E37 -> 3.2876712 | F38: On Balance Sheet
A39: Daily Amortization of Admin Fee based on reducing balance | B39: DR | C39: ACCADMINFEE | D39: Unamortised Admin Fee | E39: =E14/365 -> -0.2739726
B40: CR | C40: PL/ Income | D40: PL Category | E40: =-E39 -> 0.2739726
A43: On Installment Date | B43: DR | C43: DUEACCOUNT | D43: Principal Portion due of Installment | E43: By Core | F43: On Balance Sheet
...

Sheet Day2 - Simulated Schedule
A1: System Date | B1: 45320
A2: Offer Issue Date | B2: =+B1 -> 45320 | F2: =+XIRR(C8:C68,A8:A68) -> 0.13247654
A3: Grace Period | B3: 15 Days
A4: Offer Expiry Date | B4: =+B2+14 -> 45334 | E4: 100000 | F4: =+F5/E4 -> 0.06557076
A5: Payment Schedule | F5: =+F6/5 -> 6557.076 | M5: Generated Date: 12-Aug-2024 18:52:41
F6: =SUM(F7:F68) -> 32785.38
A7: Date | B7: Defer Date | C7: Total Due | D7: Total Cap | E7: Principal | F7: Principal Profit | G7: REC Profit | H7: Charge | I7: Tax | J7: Total Pymt | K7: Outstanding | L7: O/S Principal + Profit
A8: 45334 | C8: -98850 | D8: 0 | E8: -98850 | H8: 1000 | I8: 150 | J8: 100000 | K8: -100000
A9: 45350 | C9: 2213.09 | D9: 0 | E9: 1719.94 | F9: 493.15 | H9: 0 | K9: -98280.06
A10: 45379 | C10: 2213.09 | D10: 0 | E10: 1276.06 | F10: 937.03 | H10: 0 | K10: -97004
A11: 45410 | C11: 2213.09 | D11: 0 | E11: 1224.45 | F11: 988.64 | H11: 0 | K11: -95779.55
A12: 45440 | C12: 2213.09 | D12: 0 | E12: 1268.42 | F12: 944.67 | H12: 0 | K12: -94511.13
A13: 45471 | C13: 2213.09 | D13: 0 | E13: 1249.85 | F13: 963.24 | H13: 0 | K13: -93261.28
A14: 45501 | C14: 2213.09 | D14: 0 | E14: 1293.25 | F14: 919.84 | H14: 0 | K14: -91968.03
A15: 45532 | C15: 2213.09 | D15: 0 | E15: 1275.77 | F15: 937.32 | H15: 0 | K15: -90692.26
A16: 45563 | C16: 2213.09 | D16: 0 | E16: 1288.77 | F16: 924.32 | H16: 0 | K16: -89403.49
A17: 45593 | C17: 2213.09 | D17: 0 | E17: 1331.3 | F17: 881.79 | H17: 0 | K17: -88072.19
A18: 45624 | C18: 2213.09 | D18: 0 | E18: 1315.48 | F18: 897.61 | H18: 0 | K18: -86756.71
A19: 45654 | C19: 2213.09 | D19: 0 | E19: 1357.41 | F19: 855.68 | H19: 0 | K19: -85399.3
A20: 45685 | C20: 2213.09 | D20: 0 | E20: 1342.72 | F20: 870.37 | H20: 0 | K20: -84056.58
... A68: 47146 | C68: 2213.07 | D68: 0 | E68: 2190.72 | F68: 22.35 | H68: 0 | K68: 0

Sheet Day4-Cooling Period Cancelation
A1: Cancellation – Cooling Period
A2: Stage | B2: Debit/Credit | C2: Accounting Entries | D2: Description | E2: Core/ Customized | F2: Account Reflection
A3: Reversal of Admin Fee | B3: DR | C3: PL/ Income | D3: Income GL | E3: By Core | F3: On Balance Sheet
B4: CR | C4: Customer A/c. | D4: Disbursment/Repayment Account | E4: By Core | F4: On Balance Sheet
B5: DR | C5: VAT Payable | D5: VAT Payable | E5: By Core | F5: On Balance Sheet
B6: CR | C6: Customer A/c. | D6: Disbursment/Repayment Account | E6: By Core | F6: On Balance Sheet
A7: Reversal of Profit | B7: DR | C7: PL/ Income | D7: PL Category | E7: By Core | F7: On Balance Sheet
B8: CR | C8: ACCDEFPFT | D8: Unearned Profit | E8: By Core | F8: On Balance Sheet
B9: DR | C9: ACCDEFPFT | D9: Unearned Profit | E9: By Core | F9: On Balance Sheet
B10: CR | C10: RECDEFPFT | D10: Profit Receivable | E10: By Core | F10: On Balance Sheet
A11: Principal Settlement | B11: DR | C11: Customer A/c. | D11: Disbursment/Repayment Account | E11: By Core | F11: On Balance Sheet
B12: CR | C12: CURACCOUNT | D12: Outstanding Principal Amount | E12: By Core | F12: On Balance Sheet
A14: SADAD ENTRY
A15: Stage | B15: Debit/Credit | C15: Accounting Entries | D15: Description | E15: Core/ Customized
A16: Recovery Entry 24-04-2024 | B16: DR | D16: BF Bank Account | E16: -14988.5
B17: CR | D17: Internal Account | E17: 14988.5
A19: SADAD Fee Entry - 24-04-2024 | B19: DR | D19: PL - Expense | E19: -10
B20: CR | D20: Internal Account | E20: 10
A22: VAT Entry - 24-04-2024 | B22: DR | D22: VAT Asset | E22: -1.5
B23: CR | D23: Internal Account | E23: 1.5
A26: Transfer of Funds to Settlement Acocunt 24-04-2024 | B26: DR | D26: Internal Account | E26: -15000
B27: CR | D27: Customer Account - Settlement account | E27: 15000
A30: Instalment Settlement Entry - 28-04-2024 | B30: DR | D30: Customer Account - settlement account | E30: -15000
B31: CR | D31: Receivable (total bill amount) - loan account | E31: 15000

Sheet Day4 - Deferment
A1: Deferment - Original
A4: Payment Schedule | M4: Generated Date: 16-Aug-2024 16:24:21
A6: Date | B6: Defer Date | C6: Total Due | D6: Total Cap | E6: Principal | F6: Principal Profit | G6: REC Profit | H6: Charge | I6: Tax | J6: Total Pymt | K6: Outstanding | L6: O/S Principal + Profit
A7: 45320 | C7: 1150 | D7: 0 | E7: 100000 | H7: 1000 | I7: 150 | J7: 100000 | K7: '-100,000.00' | L7: '-132,785.38'
A8: 45350 | C8: 2213.09 | D8: 0 | E8: 1244.5 | G8: 968.59 | H8: 0 | K8: '-98,755.50' | L8: '-130,572.29'
A9: 45379 | C9: 2213.09 | D9: 0 | E9: 1288.44 | G9: 924.65 | H9: 0 | K9: '-97,467.06' | L9: '-128,359.20'
A10: 45410 | C10: 2213.09 | D10: 0 | E10: 1237.56 | G10: 975.53 | H10: 0 | K10: '-96,229.50' | L10: '-126,146.11'
A11: 45440 | C11: 2213.09 | D11: 0 | E11: 1281.02 | G11: 932.07 | H11: 0 | K11: '-94,948.48' | L11: '-123,933.02'
A12: 45471 | C12: 2213.09 | D12: 0 | E12: 1262.77 | G12: 950.32 | H12: 0 | K12: '-93,685.71' | L12: '-121,719.93'
A13: 45501 | C13: 2213.09 | D13: 0 | E13: 1305.66 | G13: 907.43 | H13: 0 | K13: '-92,380.05' | L13: '-119,506.84'
A14: 45532 | C14: 2213.09 | D14: 0 | E14: 1288.48 | G14: 924.61 | H14: 0 | K14: '-91,091.57' | L14: '-117,293.75'
A15: 45563 | C15: 2213.09 | D15: 0 | E15: 1301.37 | G15: 911.72 | H15: 0 | K15: '-89,790.20' | L15: '-115,080.66'
A16: 45593 | C16: 2213.09 | D16: 0 | E16: 1343.39 | G16: 869.7 | H16: 0 | K16: '-88,446.81' | L16: '-112,867.57'
A17: 45624 | C17: 2213.09 | D17: 0 | E17: 1327.84 | G17: 885.25 | H17: 0 | K17: '-87,118.97' | L17: '-110,654.48'
A18: 45654 | C18: 2213.09 | D18: 0 | E18: 1369.26 | G18: 843.83 | H18: 0 | K18: '-85,749.71' | L18: '-108,441.39'
A19: 45685 | C19: 2213.09 | D19: 0 | E19: 1354.84 | G19: 858.25 | H19: 0 | K19: '-84,394.87' | L19: '-106,228.30'
... A66: 47115 | C66: 2213.09 | D66: 0 | E66: 2170.84 | G66: 42.25 | H66: 0 | K66: '-2,191.16' | L66: '-2,213.07'
A67: 47146 | C67: 2213.07 | D67: 0 | E67: 2191.16 | G67: 21.91 | H67: 0 | K67: 0 | L67: 0
A70: Deferment - Term Increased
A72: Payment Schedule | K72: Generated Date: 16-Aug-2024 16:18:24
A74: Date | B74: Defer Date | C74: Total Due | D74: Total Cap | E74: Principal | F74: Profit | G74: Charge | H74: Tax | I74: Total Pymt | J74: Outstanding
A75: 45320 | C75: 101150 | D75: 0 | E75: 100000 | G75: 1000 | H75: 150 | I75: 100000 | J75: '-100,000.00'
A76: 45350 | C76: 0 | D76: 0 | G76: 0 | J76: '-100,000.00'
A77: 45379 | C77: 0 | D77: 0 | G77: 0 | J77: '-100,000.00'
A78: 45410 | C78: 2213.09 | D78: 0 | E78: 0 | G78: 0 | J78: '-100,000.00'
A79: 45440 | C79: 2213.09 | D79: 0 | E79: 692.33 | G79: 0 | J79: '-99,307.67'
A80: 45471 | C80: 2213.09 | D80: 0 | E80: 1290.06 | G80: 0 | J80: '-98,017.61'
A81: 45501 | C81: 2213.09 | D81: 0 | E81: 1331.44 | G81: 0 | J81: '-96,686.17'
A82: 45532 | C82: 2213.09 | D82: 0 | E82: 1314.43 | G82: 0 | J82: '-95,371.74'
A83: 45563 | C83: 2213.09 | D83: 0 | E83: 1326.64 | G83: 0 | J83: '-94,045.10'
A84: 45593 | C84: 2213.09 | D84: 0 | E84: 1367.17 | G84: 0 | J84: '-92,677.93'
A85: 45624 | C85: 2213.09 | D85: 0 | E85: 1351.68 | G85: 0 | J85: '-91,326.25'
A86: 45654 | C86: 2213.09 | D86: 0 | E86: 1391.63 | G86: 0 | J86: '-89,934.62'
A87: 45685 | C87: 2213.09 | D87: 0 | E87: 1377.18 | G87: 0 | J87: '-88,557.44'
A88: 45716 | C88: 2213.09 | D88: 0 | E88: 1389.98 | G88: 0 | J88: '-87,167.46'
A89: 45744 | C89: 2213.09 | D89: 0 | E89: 1481.3 | G89: 0 | J89: '-85,686.16'
... A136: 47177 | C136: 2213.09 | D136: 0 | E136: 2172.5 | G136: 0 | J136: '-2,194.59'
A137: 47205 | C137: 2213.07 | D137: 0 | E137: 2194.59 | G137: 0 | J137: 0
A140: Deferment - Add Residual
A142: Payment Schedule | K142: Generated Date: 16-Aug-2024 16:21:17
...

Sheet Day4 - Early Settlement
A1: Date | B1: Defer Date | C1: Total Due | D1: Total Cap | E1: Principal | F1: Principal Profit | G1: REC Profit | H1: Charge | I1: Tax | J1: Total Pymt | K1: Outstanding | L1: O/S Principal + Profit
A2: 45351 | C2: 1150 | D2: 0 | E2: 100000 | H2: 1000 | I2: 150 | J2: 100000 | K2: '-100,000.00' | L2: '-105,459.11'
A3: 45352 | B3: customer request
A4: 45378 | B4: payoff
A5: 45379 | C5: 11460.72 | D5: 0 | E5: 8021.14 | G5: 767.12 | H5: 2672.46 | K5: -39249.3 | L5: '-43,941.29'
A6: 45381 | B6: payoff request
A7: 45410 | C7: 3994.66 | D7: 0 | E7: 3227.05 | G7: 767.61 | H7: 0 | K7: -36022.25 | L7: '-39,946.63'
A8: 45440 | C8: 3994.66 | D8: 0 | E8: 3312.89 | G8: 681.77 | H8: 0 | K8: -32709.36 | L8: '-35,951.97'
A9: 45471 | C9: 3994.66 | D9: 0 | E9: 3354.95 | G9: 639.71 | H9: 0 | K9: -29354.41 | L9: '-31,957.31'
A10: 45501 | C10: 3994.66 | D10: 0 | E10: 3439.09 | G10: 555.57 | H10: 0 | K10: -25915.32 | L10: '-27,962.65'
A11: 45532 | C11: 3994.66 | D11: 0 | E11: 3487.83 | G11: 506.83 | H11: 0 | K11: -22427.49 | L11: '-23,967.99'
A12: 45563 | C12: 3994.66 | D12: 0 | E12: 3556.04 | G12: 438.62 | H12: 0 | K12: -18871.45 | L12: '-19,973.33'
A13: 45593 | C13: 3994.66 | D13: 0 | E13: 3637.49 | G13: 357.17 | H13: 0 | K13: -15233.96 | L13: '-15,978.67'
A14: 45624 | C14: 3994.66 | D14: 0 | E14: 3696.73 | G14: 297.93 | H14: 0 | K14: -11537.23 | L14: '-11,984.01'
A15: 45654 | C15: 3994.66 | D15: 0 | E15: 3776.3 | G15: 218.36 | H15: 0 | K15: -7760.93 | L15: '-7,989.35'
A16: 45685 | C16: 3994.66 | D16: 0 | E16: 3842.88 | G16: 151.78 | H16: 0 | K16: -3918.05 | L16: '-3,994.69'
A17: 45716 | C17: 3994.69 | D17: 0 | E17: 3918.05 | G17: 76.64 | H17: 0 | K17: 0 | L17: 0
B19: Payoff invoice generation date | C19: 45381 | D19: 45379
B20: Principal O/s | C20: =-K5 -> 39249.3 | D20: =+C20 -> 39249.3
B21: Profit Current month installment | C21: =+G7 -> 767.61
B22: Payoff Charge | C22: =SUM(G8:G10) -> 1877.05 | D22: =SUM(G7:G9) -> 2089.09
B23: Payoff Invoice Amount- Total | C23: =SUM(C20:C22) -> 41893.96 | D23: =SUM(D20:D22) -> 41338.39
A41: Payment Schedule | M41: Generated Date: 12-Jun-2024 18:26:24
A43: Date | B43: Defer Date | C43: Total Due | D43: Total Cap | E43: Principal | F43: Principal Profit | G43: REC Profit | H43: Charge | I43: Tax | J43: Total Pymt | K43: Outstanding | L43: O/S Principal + Profit
A44: 45351 | C44: 1150 | D44: 0 | E44: 100000 | H44: 1000 | I44: 150 | J44: 100000 | K44: '-100,000.00' | L44: '-105,459.11'
A45: 45368 | B45: the customer will send request for early sttlement and on 19-Mar-24 it will expire
A46: 45371 | B46: early settlement bill expiry date
A47: =A48-7 -> 45372 | B47: sadad bill issuance
A48: 45379 | C48: 11460.72 | D48: 0 | E48: 8021.14 | G48: 767.12 | H48: 2672.46 | K48: '-39,249.30' | L48: '-43,941.29'
A49: 45410 | C49: 3994.66 | D49: 0 | E49: 3227.05 | G49: 767.61 | H49: 0 | K49: '-36,022.25' | L49: '-39,946.63'
A50: 45440 | C50: 3994.66 | D50: 0 | E50: 3312.89 | G50: 681.77 | H50: 0 | K50: '-32,709.36' | L50: '-35,951.97'
A51: 45471 | C51: 3994.66 | D51: 0 | E51: 3354.95 | G51: 639.71 | H51: 0 | K51: '-29,354.41' | L51: '-31,957.31'
A52: 45501 | C52: 3994.66 | D52: 0 | E52: 3439.09 | G52: 555.57 | H52: 0 | K52: '-25,915.32' | L52: '-27,962.65'
A53: 45532 | C53: 3994.66 | D53: 0 | E53: 3487.83 | G53: 506.83 | H53: 0 | K53: '-22,427.49' | L53: '-23,967.99'
A54: 45563 | C54: 3994.66 | D54: 0 | E54: 3556.04 | G54: 438.62 | H54: 0 | K54: '-18,871.45' | L54: '-19,973.33'
A55: 45593 | C55: 3994.66 | D55: 0 | E55: 3637.49 | G55: 357.17 | H55: 0 | K55: '-15,233.96' | L55: '-15,978.67'
A56: 45624 | C56: 3994.66 | D56: 0 | E56: 3696.73 | G56: 297.93 | H56: 0 | K56: '-11,537.23' | L56: '-11,984.01'
A57: 45654 | C57: 3994.66 | D57: 0 | E57: 3776.3 | G57: 218.36 | H57: 0 | K57: '-7,760.93' | L57: '-7,989.35'
A58: 45685 | C58: 3994.66 | D58: 0 | E58: 3842.88 | G58: 151.78 | H58: 0 | K58: '-3,918.05' | L58: '-3,994.69'
A59: 45716 | C59: 3994.69 | D59: 0 | E59: 3918.05 | G59: 76.64 | H59: 0 | K59: 0 | L59: 0
...

Sheet Day4 - IRR & Flat Rate
A1: Simulation Details
A2: System Date | B2: 45322
A3: Amount | B3: 200000 | C3: Profit Start Date | D3: 45337
A4: Rate | B4: 0.12 | C4: Total Profit | D4: =SUM(F13:F24) -> 11995.63 | E4: =+D7*1*B3 -> 12545.573
A5: Term | B5: 1Y | C5: Instalment Amount | D5: =+C13 -> 17666.3
A6: 1st Instalment Date | B6: 45350 | C6: APR | D6: 0.153299 | J6: =+XIRR(J12:J24,A12:A24) -> 0.15329998
A7: Last Intalment Date | B7: 45685 | C7: Flat Rate | D7: =(D4/(A24-A12)*365)/B3 -> 0.062727865
A8: Simulation Reference | B8: AASIM240312PJW03LG | C8: # on Accrual Days | D8: =+B7-D3 -> 348 | E8: Arrangement | F8: AA24031JMN87
A10: Payment Schedule
A11: Date | B11: Defer Date | C11: Total Due | D11: Total Cap | E11: Principal | F11: Principal Profit | G11: REC Profit = IRR | H11: Charge | I11: Tax | J11: Total Pymt | K11: Outstanding
A12: 45336 | C12: 2300 | D12: 0 | E12: 200000 | H12: 2000 | I12: 300 | J12: =C12-E12 -> -197700 | K12: -200000
A13: 45350 | B13: =A13-D3 -> 13 | C13: 17666.3 | D13: 0 | E13: 16811.51 | F13: 854.79 | G13: =(F13/B13*365)/-K12 -> 0.11999937 | H13: 0 | J13: =+C13 -> 17666.3 | K13: -183188.49
A14: 45379 | B14: =A14-A13 -> 29 | C14: 17666.3 | D14: 0 | E14: 15919.74 | F14: 1746.56 | G14: =(F14/B14*365)/-K13 -> 0.11999971 | H14: 0 | J14: =+C14 -> 17666.3 | K14: -167268.75
A15: 45410 | B15: =A15-A14 -> 31 | C15: 17666.3 | D15: 0 | E15: 15961.53 | F15: 1704.77 | G15: =(F15/B15*365)/-K14 -> 0.12000025 | H15: 0 | J15: =+C15 -> 17666.3 | K15: -151307.22
A16: 45440 | B16: =A16-A15 -> 30 | C16: 17666.3 | D16: 0 | E16: 16173.96 | F16: 1492.34 | G16: =(F16/B16*365)/-K15 -> 0.11999958 | H16: 0 | J16: =+C16 -> 17666.3 | K16: -135133.26
A17: 45471 | B17: =A17-A16 -> 31 | C17: 17666.3 | D17: 0 | E17: 16289.05 | F17: 1377.25 | G17: =(F17/B17*365)/-K16 -> 0.12000012 | H17: 0 | J17: =+C17 -> 17666.3 | K17: -118844.21
A18: 45501 | B18: =A18-A17 -> 30 | C18: 17666.3 | D18: 0 | E18: 16494.14 | F18: 1172.16 | G18: =(F18/B18*365)/-K17 -> 0.11999979 | H18: 0 | J18: =+C18 -> 17666.3 | K18: -102350.07
A19: 45532 | B19: =A19-A18 -> 31 | C19: 17666.3 | D19: 0 | E19: 16623.17 | F19: 1043.13 | G19: =(F19/B19*365)/-K18 -> 0.12000006 | H19: 0 | J19: =+C19 -> 17666.3 | K19: -85726.9
A20: 45563 | B20: =A20-A19 -> 31 | C20: 17666.3 | D20: 0 | E20: 16792.59 | F20: 873.71 | G20: =(F20/B20*365)/-K19 -> 0.12000003 | H20: 0 | J20: =+C20 -> 17666.3 | K20: -68934.31
A21: 45593 | B21: =A21-A20 -> 30 | C21: 17666.3 | D21: 0 | E21: 16986.4 | F21: 679.9 | G21: =(F21/B21*365)/-K20 -> 0.11999999 | H21: 0 | J21: =+C21 -> 17666.3 | K21: -51947.91
A22: 45624 | B22: =A22-A21 -> 31 | C22: 17666.3 | D22: 0 | E22: 17136.86 | F22: 529.44 | G22: =(F22/B22*365)/-K21 -> 0.11999961 | H22: 0 | J22: =+C22 -> 17666.3 | K22: -34811.05
A23: 45654 | B23: =A23-A22 -> 30 | C23: 17666.3 | D23: 0 | E23: 17322.96 | F23: 343.34 | G23: =(F23/B23*365)/-K22 -> 0.11999935 | H23: 0 | J23: =+C23 -> 17666.3 | K23: -17488.09
A24: 45685 | B24: =A24-A23 -> 31 | C24: 17666.33 | D24: 0 | E24: 17488.09 | F24: 178.24 | G24: =(F24/B24*365)/-K23 -> 0.12000351 | H24: 0 | J24: =+C24 -> 17666.33 | K24: 0
B25: =SUM(B13:B24) -> 348 | D25: =B51-B25 -> 15 | F25: =SUM(F13:F24) -> 11995.63
A26: Arrangement / Contract Details
A27: System Date | B27: 45322
A28: Amount | B28: 200000 | C28: Profit Start Date | D28: 45322
A29: Rate | B29: =+I39 -> 0.11056697 | C29: Total Profit | D29: =SUM(G39:G50) -> 11995.63 | F29: IRR | G29: =+B4 -> 0.12 | J29: =B29-G29 -> -0.0094330268
A30: Term | B30: 1Y | C30: Instalment Amount | D30: =+C39 -> 17666.3
A31: 1st Instalment Date | B31: 45350 | C31: APR | D31: 0.141284 | F31: =D29/B28 -> 0.05997815
A32: Last Intalment Date | B32: 45685 | C32: Flat Rate | D32: =(D29/(A50-A38)*365)/B28 -> 0.060308608 | E32: =+D32*B28 -> 12061.722
A33: Arrangement Reference | B33: AA24031HGFQ5 | C33: # on Accrual Days | D33: =+B32-D28 -> 363
A34: IS Contract | B34: IS24031XRVB9
A36: Payment Schedule
A37: Date | B37: Defer Date | C37: Total Due | D37: Total Cap | E37: Principal | F37: Principal Profit | G37: REC Profit | H37: Charge | I37: Tax | J37: Total Pymt | K37: Outstanding | L37: O/S Principal + Profit
A38: 45322 | C38: 2300 | D38: 0 | E38: 200000 | H38: 2000 | I38: 300 | J38: 200000 | K38: -200000 | L38: '-211,995.63'
A39: 45350 | B39: =+A39-A38 -> 28 | C39: 17666.3 | D39: 0 | E39: 15969.93 | G39: 1696.37 | H39: 0 | I39: =(G39/B39*365)/-K38 -> 0.11056697 | K39: -184030.07 | L39: '-194,329.33'
A40: 45379 | B40: =+A40-A39 -> 29 | C40: 17666.3 | D40: 0 | E40: 16049.63 | G40: 1616.67 | H40: 0 | I40: =(G40/B40*365)/-K39 -> 0.11056749 | K40: -167980.44 | L40: '-176,663.03'
A41: 45410 | B41: =+A41-A40 -> 31 | C41: 17666.3 | D41: 0 | E41: 16088.85 | G41: 1577.45 | H41: 0 | I41: =(G41/B41*365)/-K40 -> 0.11056764 | K41: -151891.59 | L41: '-158,996.73'
A42: 45440 | B42: =+A42-A41 -> 30 | C42: 17666.3 | D42: 0 | E42: 16285.95 | G42: 1380.35 | H42: 0 | I42: =(G42/B42*365)/-K41 -> 0.1105674 | K42: -135605.64 | L42: '-141,330.43'
...

Sheet Day4 - Product Setup
A6: Personal Finance - Personal Finance Product (New Finance, Restructured Finance, Buy-out Finance and Top-up Finance)
A7: Product | B7: Product Attributes | C7: T24 Table Name | D7: T24 Field Name | E7: FREquency in which the Interest is Paid/Collected | F7: Business Values | H7: Is given business rule fixed for all Contracts or can be modified at Contract level | I7: If there is a change in the business rule, for example an interest rate change, does it affect existing Contracts also or only new Contracts | J7: RESETTING - During any Renewal Activities (for eg : change.product, rollover or reset) the property conditions will be reset from the product. NON-RESETTING - During any Renewal Activities property conditions will be maintained from the Arrangement level. | K7: Comments
B8: Currency | C8: AA.PRODUCT.DESIGNER | D8: CURRENCY | E8: Allowed Currency to open contract | F8: SAR | H8: FIXED
B9: Mode of Operation | C9: AA.PRD.DES.CUSTOMER | D9: CUSTOMER/ROLE | E9: Single Person / More than 1 person allowed | F9: Single | H9: FIXED
B10: Eligibility | C10: AA.PRD.DES.ELIGIBILITY | D10: RULE | E10: Customer eligibility criteria to get into the Contract like Age,Customer Group etc | F10: NO | H10: FIXED
B11: IBAN | C11: AA.PRD.DES.ACCOUNT | D11: ALD.ID.TYPE | E11: Is IBAN applicable | F11: NO | H11: FIXED
B12: Legacy Contract ID | C12: AA.PRD.DES.ACCOUNT | D12: ALD.ID.TYPE | E12: Legacy Contract ID (Data Migration) | F12: NO
B13: Category | C13: AA.PRD.DES.ACCOUNT | D13: CATEGORY | E13: GL Category(can be filled later) | F13: TO BE SHARED BY FINANCE
B14: Base Date | C14: AA.PRD.DES.ACCOUNT | D14: BASE.DATE | E14: What should be the Base date to considered, Contract Date or Disbursement Date | F14: Disbursement Date | H14: FIXED
B15: Date Convention | C15: AA.PRD.DES.ACCOUNT | D15: DATE.CONVENTION | E15: What should be the days convention to collect the Interest & Charges if the collection days is Holiday like Forward, Backward, Forward Same Month | F15: CALENDER | H15: NEGOTIABLE
B16: Limit | C16: AA.PRD.DES.LIMIT | D16: LIMIT.REFERENCE | E16: Is Limit applicable for this product? | F16: YES | H16: Negotiable
B17: Credit Check | C17: AC.BALANCE.TYPE | D17: EXCLUDE.CR.CHECK | E17: Determines whether Limit should be hit during Transactions like Disbursement, Make Due etc (This should be set in every Balance type created for the Property like Principal, Interest & Charges) | F17: only principal | H17: Negotiable
B18: Alerts | C18: AA.PRD.DES.ALERTS | D18: EVENT | E18: Mobile Alerts required | F18: YES | H18: Negotiable
B19: Messaging/Advices | C19: AA.PRD.DES.ACTIVITY.MESSAGING | D19: ADVICE | E19: Print advices sent to Customer like Loan Sanction Letter, Disbursement, schedule etc | F19: YES
B20: Change Product | C20: AA.PRD.DES.CHANGE.PRODUCT | D20: Config | E20: Can this Loan can be modified into other Loan products? | F20: N/A | H20: FIXED
B21: Charge Override | C21: AA.PRD.DES.CHARGE.OVERRIDE | E21: Will the Product allow Charge waive - Fixed Charge ? | F21: N/A | H21: NEGOTIABLE
B22: Constraint/Restriction | C22: AA.PRD.DES.CONSTRAINT | E22: AA Loan has a privilege of doing Backdated activities, Do you want to allow or Restrict. Setup required to restrict | F22: NO | H22: NEGOTIABLE
B23: Overdue | C23: AA.PRD.DES.OVERDUE | E23: Business process of Unpaid Loan Dues | F23: YES
A24: Interest/profit | B24: Product Attributes | C24: T24 Table Name | D24: T24 Field Name | E24: Rules | F24: Principal Profit | G24: Penalty / Charity Interest | H24: Is given business rule fixed for all Contracts or can be modified at Contract level | I24: If there is a change in the business rule, for example an interest rate change, does it affect existing Contracts also or only new Contracts | J24: RESETTING - During any Renewal Activities (for eg : change.product, rollover or reset) the property conditions will be reset from the product. NON-RESETTING - During any Renewal Activities property conditions will be maintained from the Arrangement level. | K24: Comments
B25: Accrual Frequency | C25: AA.ACCRUAL.FREQUENCY | D25: DEFAULT.LCY/FCY | E25: Daily or Monthly or Quarterly | F25: Daily | G25: N/A
B26: Interest Schedule | C26: AA.PRD.DES.PAYMENT.SCHEDULE | D26: FREQUENCY | E26: Frequency in which the Interest is Paid/Collected | F26: Monthly(EMI) | G26: N/A | H26: Negotiable
A27: Loan frequency must match with customer salary date | B27: Collection Method | C27: AA.PRD.DES.PAYMENT.SCHEDULE | D27: PAYMENT.METHOD | E27: Always Due to collect from the Customer on the Scheduled Date | F27: Due | G27: N/A
B28: Interest Basis | C28: AA.PRD.DES.INTEREST | D28: DAY.BASIS | E28: Interest calculation method (360/360, 366/365, 366/360) | F28: Actual/365 = E | G28: N/A
B29: Accrual Rule | C29: AA.PRD.DES.INTEREST | D29: ACCRUAL.RULE | E29: Actual days balance to be included for Accruals (First, Last & Both) | F29: First | G29: N/A | H29: Negotiable
B30: Threshold | C30: AA.PRD.DES.INTEREST | D30: CALC.THRESHOLD | E30: NA | F30: N/A | G30: N/A
B31: Interest Type | C31: AA.PRD.DES.INTEREST | E31: Fixed or Floating or Periodic | F31: Fixed | G31: N/A | H31: Negotiable
E32: Fixed Rate | F32: will come from LOS | G32: N/A | H32: Negotiable
E33: Floating Rate(linke to Internal Bank Index) | F33: N/A | G33: N/A | H33: Negotiable
E34: Fixed Rate (Linked to External Index such as AEIBOR , or varies according to Amount). | F34: N/A | G34: N/A
B35: Rate Type | C35: AA.PRD.DES.INTEREST | D35: RATE.TYPE | E35: Specifies whether Interest definition is based on a rate or amount and in case of rate what type of rate. Reducing rate, Flat rate, Flat amount, weighted Average Rate. | F35: Reducing Rate | G35: N/A
B36: Tier Type / Interest Calculation method | C36: AA.PRD.DES.INTEREST | D36: RATE.TIER.TYPE | E36: Rules for calculation, please provide example - is it straight forward percentage on the eligible balance, or does the percentage vary depending on the balance? | F36: N/A | G36: N/A
B37: Minimum Interest | C37: AA.PRD.DES.INTEREST | D37: MIN.INT.AMOUNT | E37: Minimum Interest amount to be paid by the customer, for this product | F37: N/A | G37: N/A
B38: Minimum Interest Waive | C38: AA.PRD.DES.INTEREST | D38: MIN.INT.WAIVE | E38: If the Calculated Interest is lesser than Minimum Interest Amount, whether the Interest is to be collected or not collected from the customer | F38: N/A | G38: N/A
B39: Charges Collection | C39: AA.PRD.DES.CHARGE | D39: Config | E39: If the Contract does not contain sufficient funds for charges, what is the business process? | F39: N/A | G39: N/A
A40: Fees & Charges | B40: Product Attributes | C40: T24 Table Name | D40: T24 Field Name | E40: Rules | F40: Activity | G40: Frequency (If scheduled) | H40: Rules for calculation, if any | I40: Is given business rule fixed for all Contracts or can be modified at Contract level | J40: Transaction Name (If Activity Based) | K40: Charge Type | L40: Fixed Amount | M40: Percentage (If Calculated) | N40: Min Charge | O40: Max Charge | P40: Charge Tier | Q40: PL Category (Acctng) | R40: RESETTING - During any Renewal Activities (for eg : change.product, rollover or reset) the property conditions will be reset from the product. NON-RESETTING - During any Renewal Activities property conditions will be maintained from the Arrangement level. | S40: Comments
B41: Upfront Admin Fee | C41: AA.PRD.DES.CHARGE | D41: Config | E41: Monthly Charges Leived | F41: YES | G41: Treatment of PL credit is amortized over the life of contract through straight line method- Activity based | H41: 1% or Max. of 5000 whichever is lower | I41: Negotiable | S41: non tracking
B42: Monthly Admin Fee | C42: AA.PRD.DES.ACTIVITY.CHARGES | D42: Config | E42: Fee charged against the Loan Principal Decrease | F42: YES | G42: Monthly Installment | H42: 1% or Max. of 5000 whichever is lower and divided by No. of Installments | I42: Negotiable | K42: CALCULATED | M42: 0 | S42: non tracking
B43: Payoff Fee (Early Settlement Fee) | C43: AA.PRD.DES.ACTIVITY.CHARGES | D43: Config | E43: Loan Closure charges before Maturity | F43: YES | G43: Activity | H43: Three months Profit proceeding months if available else remaining days profit | I43: Negotiable | K43: CALCULATED | M43: 0 | S43: non tracking
B44: Partial Payment Fee | C44: AA.PRD.DES.ACTIVITY.CHARGES | D44: Config | E44: Loan repayment installment changes, changes either in Payment Amount or Decrese/Increase in Term | F44: YES | G44: Activity | H44: Three months Profit proceeding months if available else remaining days profit | I44: Negotiable | K44: CALCULATED | M44: 0 | S44: non tracking
B45: Bonus | C45: AA.PRD.DES.ACTIVITY.CHARGES | D45: Config | E45: rebate | F45: YES | G45: Activity | I45: Negotiable | S45: non tracking
...

Sheet Day4 - Partial Settlement
A1: PARTIAL SETTLEMENT - ORIGINAL (1 of 3)
A4: Payment Schedule
A5: Date | B5: Defer Date | C5: Total Due | D5: Total Cap | E5: Principal | F5: Principal Profit | G5: REC Profit | H5: Charge | I5: Tax | J5: Total Pymt | K5: Outstanding | L5: O/S Principal + Profit
A6: 44944 | C6: 2000 | D6: 0 | E6: 200000 | H6: 2000 | J6: 200000 | K6: -200000 | L6: -235967.12
A7: 44975 | C7: 13109.28 | D7: 0 | E7: 9427.43 | G7: 3681.85 | K7: -190572.57 | L7: -222857.84
A8: 45003 | C8: 13109.28 | D8: 0 | E8: 9940.5 | G8: 3168.78 | K8: -180632.07 | L8: -209748.56
A9: 45034 | C9: 13109.28 | D9: 0 | E9: 9783.98 | G9: 3325.3 | K9: -170848.09 | L9: -196639.28 | M9: System Date
A10: 45064 | C10: 13109.28 | D10: 0 | E10: 10065.56 | G10: 3043.72 | K10: -160782.53 | L10: -183530 | O10: 5 INSTALLMENT | Q10: =SUM(C10:C14) -> 65546.4
A11: 45095 | C11: 13109.28 | D11: 0 | E11: 10149.4 | G11: 2959.88 | K11: -150633.13 | L11: -170420.72 | O11: 5 PROFIT | Q11: =SUM(G11:G15) -> 12731.13 | R11: =SUM(G10:G14) -> 13655.58
A12: 45125 | C12: 13109.28 | D12: 0 | E12: 10425.7 | G12: 2683.58 | K12: -140207.43 | L12: -157311.44 | O12: 5 PRINCIPAL | Q12: =Q10-Q11 -> 52815.27 | R12: =+Q10-R11 -> 51890.82
A13: 45156 | C13: 13109.28 | D13: 0 | E13: 10528.17 | G13: 2581.11 | K13: -129679.26 | L13: -144202.16
A14: 45187 | C14: 13109.28 | D14: 0 | E14: 10721.99 | G14: 2387.29 | K14: -118957.27 | L14: -131092.88
A15: 45217 | C15: 13109.28 | D15: 0 | E15: 10990.01 | G15: 2119.27 | K15: -107967.26 | L15: -117983.6 | O15: 5 PRINCIPAL | Q15: 52815.27 | R15: =SUM(E11:E15) -> 52815.27
A16: 45248 | C16: 13109.28 | D16: 0 | E16: 11121.69 | G16: 1987.59 | K16: -96845.57 | L16: -104874.32 | O16: 5 PROFIT | Q16: 12731.13 | R16: =SUM(G11:G15) -> 12731.13
A17: 45278 | C17: 13109.28 | D17: 0 | E17: 11383.94 | G17: 1725.34 | K17: -85461.63 | L17: -91765.04 | O17: 5 INSTALLMENT | Q17: =SUM(Q15:Q16) -> 65546.4 | R17: =SUM(C11:C15) -> 65546.4 | S17: Transaction Amount
A18: 45309 | C18: 13109.28 | D18: 0 | E18: 11536 | G18: 1573.28 | K18: -73925.63 | L18: -78655.76
A19: 45340 | C19: 13109.28 | D19: 0 | E19: 11748.37 | G19: 1360.91 | K19: -62177.26 | L19: -65546.48
A20: 45369 | C20: 13109.28 | D20: 0 | E20: 12038.49 | G20: 1070.79 | K20: -50138.77 | L20: -52437.2
A21: 45400 | C21: 13109.28 | D21: 0 | E21: 12186.26 | G21: 923.02 | K21: -37952.51 | L21: -39327.92
A22: 45430 | C22: 13109.28 | D22: 0 | E22: 12433.14 | G22: 676.14 | K22: -25519.37 | L22: -26218.64
A23: 45461 | C23: 13109.28 | D23: 0 | E23: 12639.49 | G23: 469.79 | K23: -12879.88 | L23: -13109.36
A24: 45491 | C24: 13109.36 | D24: 0 | E24: 12879.88 | G24: 229.48 | K24: 0 | L24: 0
E25: =SUM(E7:E24) -> 200000 | G25: =SUM(G7:G24) -> 35967.12
A75: After 5 Inst. Compression As Advance Installment (2 of 3)
A78: Payment Schedule
A79: Date | B79: Defer Date | C79: Total Due | D79: Total Cap | E79: Principal | F79: Principal Profit | G79: REC Profit | H79: Charge | I79: Tax | J79: Total Pymt | K79: Outstanding | L79: O/S Principal + Profit
A80: 44944 | C80: 2000 | D80: 0 | E80: 200000 | H80: 2000 | J80: 200000 | K80: -200000 | L80: -235967.12
A81: 44975 | C81: 13109.28 | D81: 0 | E81: 9427.43 | G81: 3681.85 | K81: -190572.57 | L81: -222857.84
A82: 45003 | C82: 13109.28 | D82: 0 | E82: 9940.5 | G82: 3168.78 | K82: -180632.07 | L82: -209748.56
A83: 45034 | C83: 13109.28 | D83: 0 | E83: 9783.98 | G83: 3325.3 | K83: -118032.82 | L83: -131092.88
A84: 45064 | C84: 8739.53 | D84: 0 | E84: 7182.17 | G84: 1557.36 | K84: -110850.65 | L84: -122353.35
A85: 45095 | C85: 8739.53 | D85: 0 | E85: 7228.18 | G85: 1511.35 | K85: -103622.47 | L85: -113613.82
A86: 45125 | C86: 8739.53 | D86: 0 | E86: 7372.31 | G86: 1367.22 | K86: -96250.16 | L86: -104874.29
A87: 45156 | C87: 8739.53 | D87: 0 | E87: 7427.25 | G87: 1312.28 | K87: -88822.91 | L87: -96134.76
A88: 45187 | C88: 8739.53 | D88: 0 | E88: 7528.51 | G88: 1211.02 | K88: -81294.4 | L88: -87395.23
A89: 45217 | C89: 8739.53 | D89: 0 | E89: 7666.91 | G89: 1072.62 | K89: -73627.49 | L89: -78655.7
A90: 45248 | C90: 8739.53 | D90: 0 | E90: 7735.69 | G90: 1003.84 | K90: -65891.8 | L90: -69916.17
A91: 45278 | C91: 8739.53 | D91: 0 | E91: 7870.13 | G91: 869.4 | K91: -58021.67 | L91: -61176.64
A92: 45309 | C92: 8739.53 | D92: 0 | E92: 7948.46 | G92: 791.07 | K92: -50073.21 | L92: -52437.11
... A98: 45491 | C98: 8739.46 | D98: 0 | E98: 8625.65 | G98: 113.81 | K98: 0 | L98: 0
...

Sheet Day4 - Partial Settlement (RT)
A1: Partial Settlement (Revised Term)
A3: Original
A5: Payment Schedule
A6: Date | B6: Defer Date | C6: Total Due | D6: Total Cap | E6: Principal | F6: Principal Profit | G6: REC Profit | H6: Charge | I6: Tax | J6: Total Pymt | K6: Outstanding | L6: O/S Principal + Profit
A7: 45323 | C7: 5750 | D7: 0 | E7: 500000 | H7: 5000 | I7: 750 | J7: 500000 | K7: -500000 | L7: -658990.35
A8: 45350 | C8: 10983.17 | D8: 0 | E8: 6730.49 | G8: 4252.68 | H8: 0 | K8: -493269.51 | L8: -648007.18
A9: 45379 | C9: 10983.17 | D9: 0 | E9: 6476.96 | G9: 4506.21 | H9: 0 | K9: -486792.55 | L9: -637024.01 | N9: 3 INSTALLMENTS | P9: =SUM(C8:C10) -> 32949.51
A10: 45410 | C10: 10983.17 | D10: 0 | E10: 6229.44 | G10: 4753.73 | H10: 0 | K10: -480563.11 | L10: -626040.84 | N10: 3 PRINCIPAL | P10: =SUM(E8:E10) -> 19436.89
A11: 45440 | C11: 10983.17 | D11: 0 | E11: 6441.65 | G11: 4541.52 | H11: 0 | K11: -474121.46 | L11: -615057.67 | N11: 3 PROFIT | P11: =SUM(G8:G10) -> 13512.62
A12: 45471 | C12: 10983.17 | D12: 0 | E12: 6353.18 | G12: 4629.99 | H12: 0 | K12: -467768.28 | L12: -604074.5
A13: 45501 | C13: 10983.17 | D13: 0 | E13: 6562.57 | G13: 4420.6 | H13: 0 | K13: -461205.71 | L13: -593091.33
A14: 45532 | C14: 10983.17 | D14: 0 | E14: 6479.3 | G14: 4503.87 | H14: 0 | K14: -454726.41 | L14: -582108.16
A15: 45563 | C15: 10983.17 | D15: 0 | E15: 6542.58 | G15: 4440.59 | H15: 0 | K15: -448183.83 | L15: -571124.99
A16: 45593 | C16: 10983.17 | D16: 0 | E16: 6747.65 | G16: 4235.52 | H16: 0 | K16: -441436.18 | L16: -560141.82
A17: 45624 | C17: 10983.17 | D17: 0 | E17: 6672.36 | G17: 4310.81 | H17: 0 | K17: -434763.82 | L17: -549158.65
A18: 45654 | C18: 10983.17 | D18: 0 | E18: 6874.48 | G18: 4108.69 | H18: 0 | K18: -427889.34 | L18: -538175.48
A19: 45685 | C19: 10983.17 | D19: 0 | E19: 6804.65 | G19: 4178.52 | H19: 0 | K19: -421084.69 | L19: -527192.31
A20: 45716 | C20: 10983.17 | D20: 0 | E20: 6871.1 | G20: 4112.07 | H20: 0 | K20: -414213.59 | L20: -516209.14
A21: 45744 | C21: 10983.17 | D21: 0 | E21: 7329.65 | G21: 3653.52 | H21: 0 | K21: -406883.94 | L21: -505225.97
A22: 45775 | C22: 10983.17 | D22: 0 | E22: 7009.78 | G22: 3973.39 | H22: 0 | K22: -399874.16 | L22: -494242.8
A23: 45805 | C23: 10983.17 | D23: 0 | E23: 7204.2 | G23: 3778.97 | H23: 0 | K23: -392669.96 | L23: -483259.63
... A67: 47146 | C67: 10983.32 | D67: 0 | E67: 10877.14 | G67: 106.18 | H67: 0 | K67: 0 | L67: 0
E68: =SUM(E8:E67) -> 500000 | G68: =SUM(G8:G67) -> 158990.35
A70: Revised Term
A72: Payment Schedule
A73: Date | B73: Defer Date | C73: Total Due | D73: Total Cap | E73: Principal | F73: Principal Profit | G73: REC Profit | H73: Charge | I73: Tax | J73: Total Pymt | K73: Outstanding | L73: O/S Principal + Profit
A74: 45323 | C74: 5750 | D74: 0 | E74: 500000 | H74: 5000 | I74: 750 | J74: 500000 | K74: -500000 | L74: -658990.35
A75: 45350 | C75: 10983.17 | D75: 0 | E75: 7316.46 | G75: 3666.71 | H75: 0 | K75: -473246.65 | L75: -615057.67
A76: 45379 | C76: 10983.17 | D76: 0 | E76: 6620.02 | G76: 4363.15 | H76: 0 | K76: -466626.63 | L76: -604074.5
A77: 45410 | C77: 10983.17 | D77: 0 | E77: 6384.36 | G77: 4598.81 | H77: 0 | K77: -460242.27 | L77: -593091.33
A78: 45440 | C78: 10983.17 | D78: 0 | E78: 6593.6 | G78: 4389.57 | H78: 0 | K78: -453648.67 | L78: -582108.16
A79: 45471 | C79: 10983.17 | D79: 0 | E79: 6512.26 | G79: 4470.91 | H79: 0 | K79: -447136.41 | L79: -571124.99
A80: 45501 | C80: 10983.17 | D80: 0 | E80: 6718.6 | G80: 4264.57 | H80: 0 | K80: -440417.81 | L80: -560141.82
A81: 45532 | C81: 10983.17 | D81: 0 | E81: 6642.66 | G81: 4340.51 | H81: 0 | K81: -433775.15 | L81: -549158.65
A82: 45563 | C82: 10983.17 | D82: 0 | E82: 6708.12 | G82: 4275.05 | H82: 0 | K82: -427067.03 | L82: -538175.48
A83: 45593 | C83: 10983.17 | D83: 0 | E83: 6910.01 | G83: 4073.16 | H83: 0 | K83: -420157.02 | L83: -527192.31
A84: 45624 | C84: 10983.17 | D84: 0 | E84: 6842.34 | G84: 4140.83 | H84: 0 | K84: -413314.68 | L84: -516209.14
A85: 45654 | C85: 10983.17 | D85: 0 | E85: 7041.17 | G85: 3942 | H85: 0 | K85: -406273.51 | L85: -505225.97
A86: 45685 | C86: 10983.17 | D86: 0 | E86: 6979.17 | G86: 4004 | H86: 0 | K86: -399294.34 | L86: -494242.8
... A131: 47054 | C131: 10983.32 | D131: 0 | E131: 10879.53 | G131: 103.79 | H131: 0 | K131: 0 | L131: 0
...

Sheet Day4 - Principal Decrease - Ins
A1: Original
A3: Payment Schedule | M3: Generated Date: 18-Aug-2024 19:58:09
A5: Date | B5: Defer Date | C5: Total Due | D5: Total Cap | E5: Principal | F5: Principal Profit | G5: REC Profit | H5: Charge | I5: Tax | J5: Total Pymt | K5: Outstanding | L5: O/S Principal + Profit
A6: 45321 | C6: 5750 | D6: 0 | E6: 500000 | H6: 5000 | I6: 750 | J6: 500000 | K6: '-500,000.00' | L6: '-572,552.76'
A7: 45350 | C7: 9542.55 | D7: 0 | E7: 7367.4 | G7: 2175.15 | K7: '-492,632.60' | L7: '-563,010.21'
A8: 45379 | C8: 9542.55 | D8: 0 | E8: 7399.45 | G8: 2143.1 | K8: '-485,233.15' | L8: '-553,467.66'
A9: 45410 | C9: 9542.55 | D9: 0 | E9: 7286.06 | G9: 2256.49 | K9: '-477,947.09' | L9: '-543,925.11'
A10: 45440 | C10: 9542.55 | D10: 0 | E10: 7391.64 | G10: 2150.91 | K10: '-470,555.45' | L10: '-534,382.56'
A11: 45471 | C11: 9542.55 | D11: 0 | E11: 7354.31 | G11: 2188.24 | K11: '-463,201.14' | L11: '-524,840.01'
A12: 45501 | C12: 9542.55 | D12: 0 | E12: 7458 | G12: 2084.55 | K12: '-455,743.14' | L12: '-515,297.46'
A13: 45532 | C13: 9542.55 | D13: 0 | E13: 7423.2 | G13: 2119.35 | H13: 0 | K13: '-448,319.94' | L13: '-505,754.91' | N13: 6 INSTALLMENT | O13: =SUM(C13:C18) -> 57255.3
A14: 45563 | C14: 9542.55 | D14: 0 | E14: 7457.72 | G14: 2084.83 | H14: 0 | K14: '-440,862.22' | L14: '-496,212.36' | N14: FEE | O14: =SUM(G14:G16) -> 6083.85
A15: 45593 | C15: 9542.55 | D15: 0 | E15: 7558.53 | G15: 1984.02 | H15: 0 | K15: '-433,303.69' | L15: '-486,669.81' | N15: PRINCIPAL | O15: =O13-O14 -> 51171.45
A16: 45624 | C16: 9542.55 | D16: 0 | E16: 7527.55 | G16: 2015 | H16: 0 | K16: '-425,776.14' | L16: '-477,127.26'
A17: 45654 | C17: 9542.55 | D17: 0 | E17: 7626.42 | G17: 1916.13 | H17: 0 | K17: '-418,149.72' | L17: '-467,584.71'
A18: 45685 | C18: 9542.55 | D18: 0 | E18: 7598.02 | G18: 1944.53 | H18: 0 | K18: '-410,551.70' | L18: '-458,042.16'
A19: 45716 | C19: 9542.55 | D19: 0 | E19: 7633.35 | G19: 1909.2 | H19: 0 | K19: '-402,918.35' | L19: '-448,499.61'
A20: 45744 | C20: 9542.55 | D20: 0 | E20: 7850.17 | G20: 1692.38 | H20: 0 | K20: '-395,068.18' | L20: '-438,957.06'
A21: 45775 | C21: 9542.55 | D21: 0 | E21: 7705.35 | G21: 1837.2 | H21: 0 | K21: '-387,362.83' | L21: '-429,414.51'
A22: 45805 | C22: 9542.55 | D22: 0 | E22: 7799.29 | G22: 1743.26 | H22: 0 | K22: '-379,563.54' | L22: '-419,871.96'
A23: 45836 | C23: 9542.55 | D23: 0 | E23: 7777.46 | G23: 1765.09 | H23: 0 | K23: '-371,786.08' | L23: '-410,329.41'
A24: 45866 | C24: 9542.55 | D24: 0 | E24: 7869.39 | G24: 1673.16 | H24: 0 | K24: '-363,916.69' | L24: '-400,786.86'
A25: 45897 | C25: 9542.55 | D25: 0 | E25: 7850.22 | G25: 1692.33 | H25: 0 | K25: '-356,066.47' | L25: '-391,244.31'
A26: 45928 | C26: 9542.55 | D26: 0 | E26: 7886.72 | G26: 1655.83 | H26: 0 | K26: '-348,179.75' | L26: '-381,701.76'
A27: 45958 | C27: 9542.55 | D27: 0 | E27: 7975.63 | G27: 1566.92 | H27: 0 | K27: '-340,204.12' | L27: '-372,159.21'
... A65: 47115 | C65: 9542.55 | D65: 0 | E65: 9457.24 | G65: 85.31 | H65: 0 | K65: '-9,498.15' | L65: '-9,542.31'
A66: 47146 | C66: 9542.31 | D66: 0 | E66: 9498.15 | G66: 44.16 | H66: 0 | K66: 0 | L66: 0
A69: Principal Decrease - Installment
A71: Payment Schedule | M71: Generated Date: 18-Aug-2024 20:13:24
A73: Date | B73: Defer Date | C73: Total Due | D73: Total Cap | E73: Principal | F73: Principal Profit | G73: REC Profit | H73: Charge | I73: Tax | J73: Total Pymt | K73: Outstanding | L73: O/S Principal + Profit
A74: 45321 | C74: 5750 | D74: 0 | E74: 500000 | H74: 5000 | I74: 750 | J74: 500000 | K74: '-500,000.00' | L74: '-572,552.76'
A75: 45350 | C75: 9542.55 | D75: 0 | E75: 7367.4 | G75: 2175.15 | K75: '-492,632.60' | L75: '-563,010.21'
A76: 45379 | C76: 9542.55 | D76: 0 | E76: 7399.45 | G76: 2143.1 | K76: '-485,233.15' | L76: '-553,467.66'
A77: 45410 | C77: 9542.55 | D77: 0 | E77: 7286.06 | G77: 2256.49 | K77: '-477,947.09' | L77: '-543,925.11'
A78: 45440 | C78: 9542.55 | D78: 0 | E78: 7391.64 | G78: 2150.91 | K78: '-470,555.45' | L78: '-534,382.56'
A79: 45471 | C79: 9542.55 | D79: 0 | E79: 7354.31 | G79: 2188.24 | K79: '-463,201.14' | L79: '-524,840.01'
A80: 45501 | C80: 9542.55 | D80: 0 | E80: 7458 | G80: 2084.55 | K80: '-455,743.14' | L80: '-515,297.46'
A81: 45522 | C81: 6083.85 | D81: 0 | H81: 6083.85 | K81: '-404,571.69' | L81: '-464,126.01'
A82: 45532 | C82: 8594.93 | D82: 0 | E82: 6478.84 | G82: 2116.09 | H82: 0 | K82: '-398,092.85' | L82: '-455,531.08'
A83: 45563 | C83: 8594.93 | D83: 0 | E83: 6519.47 | G83: 2075.46 | H83: 0 | K83: '-391,573.38' | L83: '-446,936.15'
...

Sheet Day4 - Principal Dec - Term
A2: Original
A4: Payment Schedule | M4: Generated Date: 18-Aug-2024 16:17:24
A6: Date | B6: Defer Date | C6: Total Due | D6: Total Cap | E6: Principal | F6: Principal Profit | G6: REC Profit | H6: Charge | I6: Tax | J6: Total Pymt | K6: Outstanding | L6: O/S Principal + Profit
A7: 45320 | C7: 4600 | D7: 0 | E7: 400000 | H7: 4000 | I7: 600 | J7: 400000 | K7: -400000 | L7: -400000
A8: 45350 | C8: 12250.33 | D8: 0 | E8: 8962.66 | G8: 3287.67 | K8: -391037.34 | L8: -394325.01
A9: 45379 | C9: 12250.33 | D9: 0 | E9: 8366.74 | G9: 3883.59 | K9: -382670.6 | L9: -389841.86
A10: 45410 | C10: 12250.33 | D10: 0 | E10: 8187.73 | G10: 4062.6 | K10: -374482.87 | L10: -385716.73
A11: 45440 | C11: 12250.33 | D11: 0 | E11: 8402.9 | G11: 3847.43 | K11: -366079.97 | L11: -381161.26
A12: 45471 | C12: 12250.33 | D12: 0 | E12: 8363.86 | G12: 3886.47 | K12: -357716.11 | L12: -376683.87
A13: 45501 | C13: 12250.33 | D13: 0 | E13: 8575.16 | G13: 3675.17 | K13: -349140.95 | L13: -371783.88 | N13: 45522
A14: 45532 | C14: 12250.33 | D14: 0 | E14: 8543.7 | G14: 3706.63 | H14: 0 | K14: -340597.25 | L14: -359533.55
A15: 45563 | C15: 12250.33 | D15: 0 | E15: 8634.4 | G15: 3615.93 | H15: 0 | K15: -331962.85 | L15: -347283.22 | N15: Fee | O15: =SUM(G15:G17) -> 10456.93
A16: 45593 | C16: 12250.33 | D16: 0 | E16: 8839.75 | G16: 3410.58 | H16: 0 | K16: -323123.1 | L16: -335032.89 | N16: Principal | O16: =O17-O15 -> 63045.05
A17: 45624 | C17: 12250.33 | D17: 0 | E17: 8819.91 | G17: 3430.42 | H17: 0 | K17: -314303.19 | L17: -322782.56 | N17: 6 Installment | O17: =SUM(C14:C19) -> 73501.98
A18: 45654 | C18: 12250.33 | D18: 0 | E18: 9021.19 | G18: 3229.14 | H18: 0 | K18: -305282 | L18: -310532.23
A19: 45685 | C19: 12250.33 | D19: 0 | E19: 9009.32 | G19: 3241.01 | H19: 0 | K19: -296272.68 | L19: -298281.9
A20: 45716 | C20: 12250.33 | D20: 0 | E20: 9104.97 | G20: 3145.36 | H20: 0 | K20: -287167.71 | L20: -286031.57
A21: 45744 | C21: 12250.33 | D21: 0 | E21: 9496.67 | G21: 2753.66 | H21: 0 | K21: -277671.04 | L21: -273781.24
A22: 45775 | C22: 12250.33 | D22: 0 | E22: 9302.45 | G22: 2947.88 | H22: 0 | K22: -268368.59 | L22: -261530.91
A23: 45805 | C23: 12250.33 | D23: 0 | E23: 9493.12 | G23: 2757.21 | H23: 0 | K23: -258875.47 | L23: -249280.58
A24: 45836 | C24: 12250.33 | D24: 0 | E24: 9501.99 | G24: 2748.34 | H24: 0 | K24: -249373.48 | L24: -237030.25
A25: 45866 | C25: 12250.33 | D25: 0 | E25: 9688.27 | G25: 2562.06 | H25: 0 | K25: -239685.21 | L25: -224779.92
A26: 45897 | C26: 12250.33 | D26: 0 | E26: 9705.73 | G26: 2544.6 | H26: 0 | K26: -229979.48 | L26: -212529.59
A27: 45928 | C27: 12250.33 | D27: 0 | E27: 9808.77 | G27: 2441.56 | H27: 0 | K27: -220170.71 | L27: -200279.26
A28: 45958 | C28: 12250.33 | D28: 0 | E28: 9988.3 | G28: 2262.03 | H28: 0 | K28: -210182.41 | L28: -188028.93
A29: 45989 | C29: 12250.33 | D29: 0 | E29: 10018.94 | G29: 2231.39 | H29: 0 | K29: -200163.47 | L29: -175778.6
... A47: 46535 | C47: 12250.47 | D47: 0 | E47: 12125.9 | G47: 124.57 | H47: 0 | K47: 0 | L47: 44727.48
A50: Principal Decrease - Term Reduction
A52: Payment Schedule | M52: Generated Date: 18-Aug-2024 16:28:08
A54: Date | B54: Defer Date | C54: Total Due | D54: Total Cap | E54: Principal | F54: Principal Profit | G54: REC Profit | H54: Charge | I54: Tax | J54: Total Pymt | K54: Outstanding | L54: O/S Principal + Profit
A55: 45320 | C55: 4600 | D55: 0 | E55: 400000 | H55: 4000 | I55: 600 | J55: 400000 | K55: '-400,000.00' | L55: '-400,000.00'
A56: 45350 | C56: 12250.33 | D56: 0 | E56: 8962.66 | G56: 3287.67 | K56: '-391,037.34' | L56: '-394,325.01'
A57: 45379 | C57: 12250.33 | D57: 0 | E57: 8366.74 | G57: 3883.59 | K57: '-382,670.60' | L57: '-389,841.86'
A58: 45410 | C58: 12250.33 | D58: 0 | E58: 8187.73 | G58: 4062.6 | K58: '-374,482.87' | L58: '-385,716.73'
A59: 45440 | C59: 12250.33 | D59: 0 | E59: 8402.9 | G59: 3847.43 | K59: '-366,079.97' | L59: '-381,161.26'
A60: 45471 | C60: 12250.33 | D60: 0 | E60: 8363.86 | G60: 3886.47 | K60: '-357,716.11' | L60: '-376,683.87'
A61: 45501 | C61: 12250.33 | D61: 0 | E61: 8575.16 | G61: 3675.17 | K61: '-349,140.95' | L61: '-371,783.88'
A62: 45522 | C62: 10456.93 | D62: 0 | H62: 10456.93 | K62: '-286,095.90' | L62: '-308,738.83'
A63: 45532 | C63: 12250.33 | D63: 0 | E63: 8334.24 | G63: 3916.09 | H63: 0 | K63: '-277,761.66' | L63: '-296,488.50'
A64: 45563 | C64: 12250.33 | D64: 0 | E64: 8021.27 | G64: 4229.06 | H64: 0 | K64: '-269,740.39' | L64: '-284,238.17'
...

Sheet DayN- APR with Flat Rate
A1: Simulation Details
A2: System Date | B2: 45323
A3: Amount | B3: 200000 | C3: Profit Start Date | D3: 45325
A4: Flat Rate | B4: 0.12 | C4: Total Profit | D4: =SUM(F13:F24) -> 23671.23
A5: Term | B5: 1Y | C5: Instalment Amount | D5: =C13 -> 18639.27
A6: 1st Instalment Date | B6: 45350 | C6: APR | D6: 0.270465
A7: Last Intalment Date | B7: 45685 | C7: IRR | D7: =G13 -> 0.21846564
A8: Simulation Reference | B8: AASIM24032MKW7FWGV | C8: # on Accrual Days | D8: =+B7-A12 -> 360 | E8: Arrangement
A11: Date | B11: Defer Date | C11: Total Due | D11: Total Cap | E11: Principal | F11: Principal Profit | G11: REC Profit | H11: Charge | I11: Tax | J11: Total Pymt | K11: Outstanding
A12: 45325 | C12: 2300 | D12: 0 | E12: 200000 | H12: 2000 | I12: 300 | J12: 200000 | K12: -200000
A13: 45350 | B13: =A13-A12 -> 25 | C13: 18639.27 | D13: 0 | E13: 15646.59 | F13: 2992.68 | G13: =(F13/B13*365)/-K12 -> 0.21846564 | H13: 0 | K13: -184353.41
A14: 45379 | B14: =A14-A13 -> 29 | C14: 18639.27 | D14: 0 | E14: 15439.35 | F14: 3199.92 | G14: =(F14/B14*365)/-K13 -> 0.21846547 | H14: 0 | K14: -168914.06
A15: 45410 | B15: =A15-A14 -> 31 | C15: 18639.27 | D15: 0 | E15: 15505.14 | F15: 3134.13 | G15: =(F15/B15*365)/-K14 -> 0.21846526 | H15: 0 | K15: -153408.92
A16: 45440 | B16: =A16-A15 -> 30 | C16: 18639.27 | D16: 0 | E16: 15884.65 | F16: 2754.62 | G16: =(F16/B16*365)/-K15 -> 0.21846541 | H16: 0 | K16: -137524.27
A17: 45471 | B17: =A17-A16 -> 31 | C17: 18639.27 | D17: 0 | E17: 16087.56 | F17: 2551.71 | G17: =(F17/B17*365)/-K16 -> 0.21846564 | H17: 0 | K17: -121436.71
A18: 45501 | B18: =A18-A17 -> 30 | C18: 18639.27 | D18: 0 | E18: 16458.74 | F18: 2180.53 | G18: =(F18/B18*365)/-K17 -> 0.21846591 | H18: 0 | K18: -104977.97
A19: 45532 | B19: =A19-A18 -> 31 | C19: 18639.27 | D19: 0 | E19: 16691.45 | F19: 1947.82 | G19: =(F19/B19*365)/-K18 -> 0.21846498 | H19: 0 | K19: -88286.52
A20: 45563 | B20: =A20-A19 -> 31 | C20: 18639.27 | D20: 0 | E20: 17001.15 | F20: 1638.12 | G20: =(F20/B20*365)/-K19 -> 0.21846531 | H20: 0 | K20: -71285.37
A21: 45593 | B21: =A21-A20 -> 30 | C21: 18639.27 | D21: 0 | E21: 17359.27 | F21: 1280 | G21: =(F21/B21*365)/-K20 -> 0.21846465 | H21: 0 | K21: -53926.1
A22: 45624 | B22: =A22-A21 -> 31 | C22: 18639.27 | D22: 0 | E22: 17638.69 | F22: 1000.58 | G22: =(F22/B22*365)/-K21 -> 0.21846606 | H22: 0 | K22: -36287.41
A23: 45654 | B23: =A23-A22 -> 30 | C23: 18639.27 | D23: 0 | E23: 17987.69 | F23: 651.58 | G23: =(F23/B23*365)/-K22 -> 0.21846576 | H23: 0 | K23: -18299.72
A24: 45685 | B24: =A24-A23 -> 31 | C24: 18639.26 | D24: 0 | E24: 18299.72 | F24: 339.54 | G24: =(F24/B24*365)/-K23 -> 0.21846289 | H24: 0 | K24: 0
E25: =SUM(E13:E24) -> 200000 | F25: =SUM(F13:F24) -> 23671.23 | H25: =SUM(H12:H24) -> 2000 | I25: =SUM(I12:I24) -> 300
A27: Arrangement Details
A28: System Date | B28: 45323
A29: Amount | B29: 200000 | C29: Profit Start Date | D29: 45323
A30: Flat Rate | B30: =(G50/D34*365)/B29 -> 0.119337 | C30: Total Profit | D30: =SUM(G38:G49) -> 23671.23
A31: Term | B31: 1Y | C31: Instalment Amount | D31: =C38 -> 18639.27
A32: 1st Instalment Date | B32: 45350 | C32: APR | D32: 0.26721
A33: Last Intalment Date | B33: 45685 | C33: IRR | D33: =F38 -> 0.21612731
A34: Arrangement Reference | B34: AA24032X111V | C34: # on Accrual Days | D34: =+B33-D29 -> 362 | F34: AASIM24032TC0MXHSX
A36: Date | B36: Defer Date | C36: Total Due | D36: Total Cap | E36: Principal | F36: Principal Profit | G36: REC Profit | H36: Charge | I36: Tax | J36: Total Pymt | K36: Outstanding
A37: 45323 | C37: 2300 | D37: 0 | E37: 200000 | H37: 2000 | I37: 300 | J37: 200000 | K37: -200000
A38: 45350 | B38: =A38-A37 -> 27 | C38: 18639.27 | D38: 0 | E38: 15441.77 | F38: =(G38/B38*365)/-K37 -> 0.21612731 | G38: 3197.5 | H38: 0 | K38: -184558.23
A39: 45379 | B39: =A39-A38 -> 29 | C39: 18639.27 | D39: 0 | E39: 15470.08 | F39: =(G39/B39*365)/-K38 -> 0.21612735 | G39: 3169.19 | H39: 0 | K39: -169088.15
A40: 45410 | B40: =A40-A39 -> 31 | C40: 18639.27 | D40: 0 | E40: 15535.48 | F40: =(G40/B40*365)/-K39 -> 0.21612765 | G40: 3103.79 | H40: 0 | K40: -153552.67
A41: 45440 | B41: =A41-A40 -> 30 | C41: 18639.27 | D41: 0 | E41: 15911.58 | F41: =(G41/B41*365)/-K40 -> 0.21612711 | G41: 2727.69 | H41: 0 | K41: -137641.09
A42: 45471 | B42: =A42-A41 -> 31 | C42: 18639.27 | D42: 0 | E42: 16112.73 | F42: =(G42/B42*365)/-K41 -> 0.21612711 | G42: 2526.54 | H42: 0 | K42: -121528.36
A43: 45501 | B43: =A43-A42 -> 30 | C43: 18639.27 | D43: 0 | E43: 16480.45 | F43: =(G43/B43*365)/-K42 -> 0.21612769 | G43: 2158.82 | H43: 0 | K43: -105047.91
A44: 45532 | B44: =A44-A43 -> 31 | C44: 18639.27 | D44: 0 | E44: 16711.01 | F44: =(G44/B44*365)/-K43 -> 0.21612716 | G44: 1928.26 | H44: 0 | K44: -88336.9
...

Sheet DayN - Proposed Acc Entries
A6: Offer Letter | C6: Purchase -
D7: Buy Broker
A10: Purchase Stage
A11: Stage | B11: Debit/Credit | C11: Accounting Entries | D11: Description | E11: Core/ Customized | F11: Account Reflection
A12: Offer Acceptance | B12: DR | C12: Inventory - IA | D12: Internal Account | E12: -10000 | H12: Finance Amount | J12: 10000
B13: CR | C13: Buy Broker's account | D13: Internal Account | E13: =-E12 -> 10000 | H13: Admin Fee 1% | J13: =J12*1% -> 100
B14: DR | C14: Buy Broker's account | D14: Internal Account | E14: =+E12 -> -10000
B15: CR | C15: TA - Bank Account | D15: Nostro Account | E15: =+E13 -> 10000
A16: Status - Request | B16: DR | C16: No Accounting Entry | G16: On Request
B17: CR
A18: Status - Approval | B18: DR | C18: GIT | D18: Goods in Transit | E18: =-J12 -> -10000 | F18: On Balance Sheet | G18: On Spot | H18: VAT | J18: =J13*15% -> 15
B19: CR | C19: Purchase Order | D19: Purchase Order | E19: =-E18 -> 10000 | F19: On Balance Sheet | H19: Net Finance Amount | J19: =J12-J13-J18 -> 9885
A20: Status - Purchase | B20: DR | C20: Purchase Order | D20: Purchase Order | E20: =-E19 -> -10000 | F20: On Balance Sheet
B21: CR | C21: GIT | D21: Goods in Transit | E21: =-E19 -> -10000 | F21: On Balance Sheet | H21: Profit Amount | I21: 0.12 | J21: =J12*I21 -> 1200
B22: DR | C22: Purchases | D22: Purchase | E22: =-J12 -> -10000 | F22: On Balance Sheet
B23: CR | C23: Inventory - IA | D23: Internal Account | E23: =-E22 -> 10000 | F23: On Balance Sheet
A24: Finance / Sale | B24: DR | C24: CURACCOUNT | D24: AA Arrangeement - ACCOUNT | E24: =-J12 -> -10000 | F24: On Balance Sheet
B25: CR | C25: Purchases | D25: Purchase | E25: =-E22 -> 10000 | F25: On Balance Sheet
B26: DR | C26: RECDEFPFT | D26: Profit Receivable | E26: =-J21 -> -1200 | F26: On Balance Sheet
B27: CR | C27: ACCDEFPFT | D27: Unearned Accrued Profit | E27: =-E26 -> 1200 | F27: On Balance Sheet
A28: Admin Fee Due with VAT | B28: Dr | C28: DUEADMINFEE | D28: Admin Fee | E28: =-J13 -> -100
B29: Cr | C29: ACCADMINFEE | D29: Unamortise Admin Fee | E29: =-E28 -> 100
B30: Dr | C30: DUEVAT | D30: VAT | E30: =-J18 -> -15
B31: Cr | C31: VAT Payable | E31: =-E30 -> 15
A32: Brokerage Fee | B32: Dr | C32: BROKERFEE - PL | D32: Brokerage Fee Expense | E32: 50
B33: Cr | C33: Internal Payable | D33: Brokerage Fee Payable | E33: =-E32 -> -50
A34: Payment to Customer | B34: DR | C34: Sell Broker's Account | D34: Internal Account | E34: -10000 | F34: On Balance Sheet
B35: CR | C35: Customer's Account | D35: Disbursment/Repayment Account | E35: 10000 | F35: On Balance Sheet
A36: Broker Settlement (incase of different) | B36: DR | C36: Buy Broker's account | D36: Internal Account | E36: =-E23 -> -10000 | F36: On Balance Sheet
B37: CR | C37: Sell Broker's Account | D37: Internal Account | E37: =-E34 -> 10000 | F37: On Balance Sheet
A38: Recovery of Admin Fee & VAT | B38: Dr | C38: Customer's Account | D38: Disbursment/Repayment Account | E38: =E28 -> -100
B39: Cr | C39: DUEADMINFEE | D39: Admin Fee | E39: =-E28 -> 100
B40: Dr | C40: Customer's Account | D40: Disbursment/Repayment Account | E40: =E30 -> -15
B41: Cr | C41: DUEVAT | D41: VAT | E41: =-E30 -> 15
A42: Actual Repayment to Customer (Net of Financing) | B42: Dr | C42: Customer's Account | D42: Disbursment/Repayment Account | E42: =E35+E38+E40 -> 9885
B43: Cr | C43: BF Account | D43: Internal Account | E43: =-E42 -> -9885
B44: Dr | C44: BF Account | D44: Internal Account | E44: =E42 -> 9885
B45: Cr | C45: Customer Bank Account | D45: XYZ bank account- customer current account | E45: =E43 -> -9885
A46: Upfront Admin Fee By Customer | B46: Dr | C46: BF Account | D46: Internal Account | E46: =E38+E40 -> -115
B47: Cr | C47: Customer's Account | D47: Disbursment/Repayment Account | E47: =-E46 -> 115
...

Sheet DayN - LOS - LMS Mapping Field
A1: Loan Application Fields | B1: Type | C1: Enabled | D1: Values | E1: Description | F1: Category | G1: Source | H1: LMS Required from LOS | I1: Technical Name | J1: Mapping | K1: Ref Fields | L1: Mandatory | M1: Built Name2
A2: Title | B2: NUMBER | C2: N | D2: 8 | E2: cg_salutation | F2: Personal Info | G2: LOS Session
A3: First Name | B3: VARCHAR2 | C3: Y | D3: 200 CHAR | E3: custfname | F3: Personal Info | G3: LOS Session
A4: Middle Name | B4: VARCHAR2 | C4: Y | D4: 200 CHAR | E4: custmname | F4: Personal Info | G4: LOS Session
A5: Third Name | B5: VARCHAR2 | C5: Y | D5: 200 CHAR | E5: custtname | F5: Personal Info | G5: LOS Session
A6: Family Name | B6: VARCHAR2 | C6: Y | D6: 200 CHAR | E6: custlname | F6: Personal Info | G6: LOS Session
A7: First Name (Arabic) | B7: VARCHAR2 | C7: Y | D7: 200 CHAR | E7: custfname_1 | F7: Personal Info | G7: LOS Session
A8: Middle Name (Arabic) | B8: VARCHAR2 | C8: Y | D8: 200 CHAR | E8: custmname_1 | F8: Personal Info | G8: LOS Session
A9: Third Name (Arabic) | B9: VARCHAR2 | C9: Y | D9: 200 CHAR | E9: custlname_1 | F9: Personal Info | G9: LOS Session
A10: Family Name (Arabic) | B10: VARCHAR2 | C10: Y | D10: 200 CHAR | E10: custfamilyname_1 | F10: Personal Info | G10: LOS Session
A11: Date of Birth | B11: DATE | C11: Y | E11: dobdoi | F11: Personal Info | G11: LOS Session
A12: Age | B12: NUMBER | C12: Y | D12: 3 | E12: age | F12: Personal Info | G12: LOS Session
A13: Nationality | B13: NUMBER | C13: Y | D13: 8 | E13: cg_nationalityid | F13: Personal Info | G13: LOS Session
A14: Gender | B14: VARCHAR2 | C14: Y | D14: 1 CHAR | E14: sex | F14: Personal Info | G14: LOS Session
A15: Social Status | B15: NUMBER | C15: Y | D15: 8 | E15: cg_maritalstatus | F15: Personal Info | G15: LOS Session
A16: Number Of Dependents | B16: NUMBER | C16: Y | D16: 8 | E16: no_of_dependents | F16: Personal Info | G16: LOS Session
A17: Type of Residence | B17: NUMBER | C17: Y | D17: 8 | E17: cg_residencetype | F17: Personal Info | G17: LOS Session
A18: National ID or Iqma Number | B18: NUMBER | C18: Y | D18: 8 | F18: Personal Info | G18: LOS Session
A19: ID type | B19: NUMBER | C19: Y | D19: 8 | E19: cg_idtype | F19: ID Info | G19: LOS Session
A20: ID Number | B20: VARCHAR2 | C20: Y | D20: 80 CHAR | E20: idnumber | F20: ID Info | G20: LOS Session
A21: ID Expiry Date | B21: DATE | C21: Y | E21: date_of_expiry | F21: ID Info | G21: LOS Session
A22: Mobile Phone | B22: NUMBER | C22: Y | D22: 10 | E22: mobile | F22: Contact Info | G22: LOS Session
A23: Mobile Phone 2 | B23: VARCHAR2 | C23: N | D23: 60 CHAR | E23: phone2 | F23: Contact Info | G23: LOS Session
A24: E-Mail | B24: VARCHAR2 | C24: Y | D24: 200 CHAR | E24: email | F24: Contact Info | G24: LOS Session
A25: Nature Of Employment | B25: NUMBER | C25: Y | D25: 8 | E25: cg_employmentstatus | F25: Employment Info | G25: LOS Session
A26: Employer Name | B26: VARCHAR2 | C26: Y | D26: 360 CHAR | E26: other_emp_busname | F26: Employment Info | G26: LOS Session
A27: Occupation/Position Job Title | B27: NUMBER | C27: N | D27: 8 | E27: cg_occupationjobtitle | F27: Employment Info | G27: LOS Session
A28: Joining Date | B28: DATE | C28: Y | E28: joiningdate | F28: Employment Info | G28: LOS Session
A29: Type of Sector | B29: NUMBER | C29: Y | D29: 8 | E29: cg_sectype | F29: Employment Info | G29: LOS Session
A30: Commercial Number | B30: VARCHAR2 | C30: N | D30: 20 CHAR | E30: commercialregistrationnumber | F30: Employment Info | G30: LOS Session
A31: Grade | F31: Employment Info | G31: LOS Session
A32: Customer Type (Civilian/Military | B32: NUMBER | C32: Y | D32: 8 | E32: cg_subsec | F32: Employment Info | G32: LOS Session
A33: Experience at Current Employment | B33: NUMBER | C33: Y | D33: 3 | E33: yearsatcurrempl | F33: Employment Info | G33: LOS Session
